Workbook

Sheet Total employees
A1: EmployeeID | B1: Department | C1: JobTitle | D1: Email | E1: Gender | F1: HireDate | G1: TerminationDate | H1: Salary | I1: ManagerID | J1: PerformanceRating | K1: Status | L1: Column12
A2: JOG-1159 | B2: Research & Development | C2: Scientist | D2: employees.1159@jogate.com | E2: Null | F2: 43120 | H2: 403 | I2: JOG-1048 | J2: 2 | K2: Active | N2: HR Analysis Project Questions and Answers
A3: JOG-1033 | B3: IT Support | C3: Help Desk Specialist | D3: employees.1033@jogate.com | E3: Female | F3: 43130 | H3: 1785 | I3: JOG-1107 | J3: 4 | K3: Active
A4: JOG-1163 | B4: Logistics | C4: Logistics Coordinator | D4: employees.1163@jogate.com | E4: Female | F4: 43138 | G4: 44980 | H4: 551 | I4: JOG-1164 | J4: 3 | K4: Terminated
A5: JOG-1014 | B5: Finance | C5: Controller | D5: employees.1014@jogate.com | E5: Female | F5: 43162 | H5: 1150 | I5: JOG-1164 | J5: 2 | K5: Active
A6: JOG-1122 | B6: Quality Control | C6: Qc Inspector | D6: employees.1122@jogate.com | E6: Null | F6: 43171 | H6: 1528 | I6: JOG-1044 | J6: 5 | K6: Active | N6: What is the average salary? | O6: The employees average salary is: | P6: =AVERAGE(H2:H201) -> 1201.815
A7: JOG-1095 | B7: Marketing | C7: Marketing Manager | D7: employees.1095@jogate.com | E7: Female | F7: 43184 | G7: 44764 | H7: 1696 | J7: 5 | K7: Terminated
A8: JOG-1131 | B8: Human Resources | C8: Hr Coordinator | D8: employees.1131@jogate.com | E8: Female | F8: 43189 | H8: 338 | I8: JOG-1174 | J8: 3 | K8: Active
A9: JOG-1052 | B9: Research & Development | C9: Research Lead | D9: employees.1052@jogate.com | E9: Female | F9: 43200 | H9: 318 | I9: JOG-1136 | J9: 2 | K9: Active
A10: JOG-1182 | B10: Sales | C10: Regional Sales Manager | D10: employees.1182@jogate.com | E10: Female | F10: 43205 | H10: 1646 | J10: 2 | K10: Active
A11: JOG-1172 | B11: Production | C11: Operations Manager | D11: employees.1172@jogate.com | E11: Male | F11: 43229 | H11: 1440 | J11: 3 | K11: Active
A12: JOG-1192 | B12: Quality Control | C12: Qc Manager | D12: employees.1192@jogate.com | E12: Null | F12: 43229 | G12: 44618 | H12: 2082 | J12: 2 | K12: Terminated
A13: JOG-1130 | B13: Human Resources | C13: Hr Generalist | D13: employees.1130@jogate.com | E13: Null | F13: 43244 | H13: 1088 | I13: JOG-1064 | J13: 3 | K13: Active
A14: JOG-1155 | B14: Human Resources | C14: Recruiter | D14: employees.1155@jogate.com | E14: Null | F14: 43263 | H14: 1236 | I14: JOG-1198 | J14: 5 | K14: Active | N14: Status | O14: (All)
A15: JOG-1084 | B15: Logistics | C15: Warehouse Associate | D15: employees.1084@jogate.com | E15: Male | F15: 43280 | H15: 1554 | I15: JOG-1120 | J15: 4 | K15: Active
A16: JOG-1144 | B16: Production | C16: Operations Manager | D16: employees.1144@jogate.com | E16: Male | F16: 43289 | H16: 814 | J16: 5 | K16: Active | N16: Count of EmployeeID | O16: Column Labels
A17: JOG-1107 | B17: Quality Control | C17: Qc Manager | D17: =_xlfn.CONCAT("employees.", RIGHT('Total employees'!$A108, 4), "@jogate.com") -> employees.1022@jogate.com | E17: Male | F17: 43292 | G17: 44267 | H17: 1594 | J17: 2 | K17: Terminated | N17: Row Labels | O17: Female | P17: Male | Q17: Null | R17: Grand Total
A18: JOG-1123 | B18: Research & Development | C18: Scientist | D18: employees.1123@jogate.com | E18: Female | F18: 43308 | H18: 1591 | I18: JOG-1044 | J18: 5 | K18: Active | N18: Finance | O18: 3 | P18: 6 | Q18: 14 | R18: 23
A19: JOG-1156 | B19: Finance | C19: Accountant | D19: employees.1156@jogate.com | E19: Null | F19: 43323 | H19: 1899 | I19: JOG-1050 | J19: 2 | K19: Active | N19: Human Resources | O19: 10 | P19: 4 | Q19: 10 | R19: 24
A20: JOG-1174 | B20: Quality Control | C20: Qc Manager | D20: employees.1174@jogate.com | E20: Null | F20: 43336 | H20: 1529 | J20: 3 | K20: Active | N20: IT Support | O20: 6 | P20: 8 | Q20: 4 | R20: 18
A21: JOG-1073 | B21: Production | C21: Line Supervisor | D21: employees.1073@jogate.com | E21: Female | F21: 43337 | G21: 44278 | H21: 1593 | I21: JOG-1050 | J21: 3 | K21: Terminated | N21: Logistics | O21: 10 | P21: 8 | Q21: 6 | R21: 24
A22: JOG-1135 | B22: Quality Control | C22: Qc Manager | D22: employees.1135@jogate.com | E22: Male | F22: 43345 | H22: 1820 | J22: 4 | K22: Active | N22: Marketing | O22: 3 | P22: 7 | Q22: 7 | R22: 17
A23: JOG-1043 | B23: Research & Development | C23: Research Lead | D23: employees.1043@jogate.com | E23: Female | F23: 43349 | G23: 45081 | H23: 1802 | I23: JOG-1107 | J23: 5 | K23: Terminated | N23: Production | O23: 13 | P23: 7 | Q23: 6 | R23: 26
A24: JOG-1117 | B24: Finance | C24: Controller | D24: employees.1117@jogate.com | E24: Null | F24: 43349 | H24: 1009 | I24: JOG-1060 | J24: 2 | K24: Active | N24: Quality Control | O24: 8 | P24: 9 | Q24: 12 | R24: 29
A25: JOG-1024 | B25: IT Support | C25: Help Desk Specialist | D25: =_xlfn.CONCAT("employees.", RIGHT('Total employees'!$A25, 4), "@jogate.com") -> employees.1024@jogate.com | E25: Female | F25: 43353 | H25: 761 | I25: JOG-1120 | J25: 4 | K25: Active | N25: Research & Development | O25: 9 | P25: 4 | Q25: 6 | R25: 19
A26: JOG-1145 | B26: Sales | C26: Sales Associate | D26: employees.1145@jogate.com | E26: Male | F26: 43404 | H26: 994 | I26: JOG-1006 | J26: 5 | K26: Active | N26: Sales | O26: 9 | P26: 4 | Q26: 7 | R26: 20
A27: JOG-1092 | B27: Production | C27: Production Worker | D27: employees.1092@jogate.com | E27: Null | F27: 43414 | H27: 466 | I27: JOG-1060 | J27: 5 | K27: Active | N27: Grand Total | O27: 71 | P27: 57 | Q27: 72 | R27: 200
A28: JOG-1020 | B28: Finance | C28: Financial Analyst | D28: =_xlfn.CONCAT("employees.", RIGHT('Total employees'!$A21, 4), "@jogate.com") -> employees.1073@jogate.com | E28: Male | F28: 43455 | G28: 44930 | H28: 1814 | I28: JOG-1064 | J28: 2 | K28: Terminated
A29: JOG-1031 | B29: Finance | C29: Accountant | D29: employees.1031@jogate.com | E29: Null | F29: 43456 | H29: 454 | I29: JOG-1144 | J29: 4 | K29: Active
A30: JOG-1136 | B30: Marketing | C30: Marketing Manager | D30: employees.1136@jogate.com | E30: Female | F30: 43472 | H30: 1933 | J30: 4 | K30: Active
A31: JOG-1152 | B31: Research & Development | C31: Lab Technician | D31: employees.1152@jogate.com | E31: Null | F31: 43474 | H31: 946 | I31: JOG-1192 | J31: 4 | K31: Active
A32: JOG-1058 | B32: IT Support | C32: Help Desk Specialist | D32: =_xlfn.CONCAT("employees.", RIGHT('Total employees'!$A59, 4), "@jogate.com") -> employees.1028@jogate.com | E32: Null | F32: 43504 | H32: 2088 | I32: JOG-1044 | J32: 4 | K32: Active
A33: JOG-1048 | B33: Research & Development | C33: Research Lead | D33: employees.1048@jogate.com | E33: Null | F33: 43519 | H33: 1258 | I33: JOG-1030 | J33: 5 | K33: Active
A34: JOG-1030 | B34: Marketing | C34: Marketing Manager | D34: employees.1030@jogate.com | E34: Male | F34: 43530 | H34: 953 | J34: 5 | K34: Active
A35: JOG-1054 | B35: Logistics | C35: Warehouse Associate | D35: =_xlfn.CONCAT("employees.", RIGHT('Total employees'!$A55, 4), "@jogate.com") -> employees.1066@jogate.com | E35: Null | F35: 43531 | H35: 1632 | I35: JOG-1095 | J35: 3 | K35: Active
A36: JOG-1093 | B36: Human Resources | C36: Hr Generalist | D36: employees.1093@jogate.com | E36: Male | F36: 43534 | G36: 44606 | H36: 1750 | I36: JOG-1095 | J36: 4 | K36: Terminated
A37: JOG-1134 | B37: Logistics | C37: Logistics Coordinator | D37: employees.1134@jogate.com | E37: Male | F37: 43545 | H37: 1986 | I37: JOG-1165 | J37: 5 | K37: Active
A38: JOG-1147 | B38: Quality Control | C38: Qc Inspector | D38: employees.1147@jogate.com | E38: Male | F38: 43553 | H38: 1250 | I38: JOG-1094 | J38: 2 | K38: Active
A39: JOG-1099 | B39: Production | C39: Operations Manager | D39: employees.1099@jogate.com | E39: Male | F39: 43560 | H39: 1039 | J39: 3 | K39: Active
A40: JOG-1140 | B40: Production | C40: Operations Manager | D40: employees.1140@jogate.com | E40: Null | F40: 43560 | H40: 448 | J40: 4 | K40: Active
...

Sheet Average salary
A1: EmployeeID | B1: Department | C1: JobTitle | D1: Email | E1: Gender | F1: HireDate | G1: TerminationDate | H1: Salary | I1: ManagerID | J1: PerformanceRating | K1: Status | L1: Column12
A2: JOG-1159 | B2: Research & Development | C2: Scientist | D2: employees.1159@jogate.com | E2: Null | F2: 43120 | H2: 403 | I2: JOG-1048 | J2: 2 | K2: Active | N2: HR Analysis Project Questions and Answers
A3: JOG-1033 | B3: IT Support | C3: Help Desk Specialist | D3: employees.1033@jogate.com | E3: Female | F3: 43130 | H3: 1785 | I3: JOG-1107 | J3: 4 | K3: Active
A4: JOG-1163 | B4: Logistics | C4: Logistics Coordinator | D4: employees.1163@jogate.com | E4: Female | F4: 43138 | G4: 44980 | H4: 551 | I4: JOG-1164 | J4: 3 | K4: Terminated
A5: JOG-1014 | B5: Finance | C5: Controller | D5: employees.1014@jogate.com | E5: Female | F5: 43162 | H5: 1150 | I5: JOG-1164 | J5: 2 | K5: Active
A6: JOG-1122 | B6: Quality Control | C6: Qc Inspector | D6: employees.1122@jogate.com | E6: Null | F6: 43171 | H6: 1528 | I6: JOG-1044 | J6: 5 | K6: Active | N6: What is the average salary? | O6: The employees average salary is: | P6: =AVERAGE(H2:H201) -> 1201.815
A7: JOG-1095 | B7: Marketing | C7: Marketing Manager | D7: employees.1095@jogate.com | E7: Female | F7: 43184 | G7: 44764 | H7: 1696 | J7: 5 | K7: Terminated
A8: JOG-1131 | B8: Human Resources | C8: Hr Coordinator | D8: employees.1131@jogate.com | E8: Female | F8: 43189 | H8: 338 | I8: JOG-1174 | J8: 3 | K8: Active
A9: JOG-1052 | B9: Research & Development | C9: Research Lead | D9: employees.1052@jogate.com | E9: Female | F9: 43200 | H9: 318 | I9: JOG-1136 | J9: 2 | K9: Active
A10: JOG-1182 | B10: Sales | C10: Regional Sales Manager | D10: employees.1182@jogate.com | E10: Female | F10: 43205 | H10: 1646 | J10: 2 | K10: Active
A11: JOG-1172 | B11: Production | C11: Operations Manager | D11: employees.1172@jogate.com | E11: Male | F11: 43229 | H11: 1440 | J11: 3 | K11: Active
A12: JOG-1192 | B12: Quality Control | C12: Qc Manager | D12: employees.1192@jogate.com | E12: Null | F12: 43229 | G12: 44618 | H12: 2082 | J12: 2 | K12: Terminated
A13: JOG-1130 | B13: Human Resources | C13: Hr Generalist | D13: employees.1130@jogate.com | E13: Null | F13: 43244 | H13: 1088 | I13: JOG-1064 | J13: 3 | K13: Active
A14: JOG-1155 | B14: Human Resources | C14: Recruiter | D14: employees.1155@jogate.com | E14: Null | F14: 43263 | H14: 1236 | I14: JOG-1198 | J14: 5 | K14: Active
A15: JOG-1084 | B15: Logistics | C15: Warehouse Associate | D15: employees.1084@jogate.com | E15: Male | F15: 43280 | H15: 1554 | I15: JOG-1120 | J15: 4 | K15: Active
A16: JOG-1144 | B16: Production | C16: Operations Manager | D16: employees.1144@jogate.com | E16: Male | F16: 43289 | H16: 814 | J16: 5 | K16: Active | N16: Row Labels | O16: Average of Salary
A17: JOG-1107 | B17: Quality Control | C17: Qc Manager | D17: =_xlfn.CONCAT("employees.", RIGHT('Average salary'!$A108, 4), "@jogate.com") -> employees.1022@jogate.com | E17: Male | F17: 43292 | G17: 44267 | H17: 1594 | J17: 2 | K17: Terminated | N17: Quality Control | O17: 1375.8966
A18: JOG-1123 | B18: Research & Development | C18: Scientist | D18: employees.1123@jogate.com | E18: Female | F18: 43308 | H18: 1591 | I18: JOG-1044 | J18: 5 | K18: Active | N18: Logistics | O18: 1365.25
A19: JOG-1156 | B19: Finance | C19: Accountant | D19: employees.1156@jogate.com | E19: Null | F19: 43323 | H19: 1899 | I19: JOG-1050 | J19: 2 | K19: Active | N19: Finance | O19: 1344.6957
A20: JOG-1174 | B20: Quality Control | C20: Qc Manager | D20: employees.1174@jogate.com | E20: Null | F20: 43336 | H20: 1529 | J20: 3 | K20: Active | N20: IT Support | O20: 1289
A21: JOG-1073 | B21: Production | C21: Line Supervisor | D21: employees.1073@jogate.com | E21: Female | F21: 43337 | G21: 44278 | H21: 1593 | I21: JOG-1050 | J21: 3 | K21: Terminated | N21: Human Resources | O21: 1087.75
A22: JOG-1135 | B22: Quality Control | C22: Qc Manager | D22: employees.1135@jogate.com | E22: Male | F22: 43345 | H22: 1820 | J22: 4 | K22: Active | N22: Production | O22: 1069.3462
A23: JOG-1043 | B23: Research & Development | C23: Research Lead | D23: employees.1043@jogate.com | E23: Female | F23: 43349 | G23: 45081 | H23: 1802 | I23: JOG-1107 | J23: 5 | K23: Terminated | N23: Sales | O23: 1068.25
A24: JOG-1117 | B24: Finance | C24: Controller | D24: employees.1117@jogate.com | E24: Null | F24: 43349 | H24: 1009 | I24: JOG-1060 | J24: 2 | K24: Active | N24: Marketing | O24: 1065.4118
A25: JOG-1024 | B25: IT Support | C25: Help Desk Specialist | D25: =_xlfn.CONCAT("employees.", RIGHT('Average salary'!$A25, 4), "@jogate.com") -> employees.1024@jogate.com | E25: Female | F25: 43353 | H25: 761 | I25: JOG-1120 | J25: 4 | K25: Active | N25: Research & Development | O25: 1062.1053
A26: JOG-1145 | B26: Sales | C26: Sales Associate | D26: employees.1145@jogate.com | E26: Male | F26: 43404 | H26: 994 | I26: JOG-1006 | J26: 5 | K26: Active | N26: Grand Total | O26: 1201.815
A27: JOG-1092 | B27: Production | C27: Production Worker | D27: employees.1092@jogate.com | E27: Null | F27: 43414 | H27: 466 | I27: JOG-1060 | J27: 5 | K27: Active
A28: JOG-1020 | B28: Finance | C28: Financial Analyst | D28: =_xlfn.CONCAT("employees.", RIGHT('Average salary'!$A21, 4), "@jogate.com") -> employees.1073@jogate.com | E28: Male | F28: 43455 | G28: 44930 | H28: 1814 | I28: JOG-1064 | J28: 2 | K28: Terminated
A29: JOG-1031 | B29: Finance | C29: Accountant | D29: employees.1031@jogate.com | E29: Null | F29: 43456 | H29: 454 | I29: JOG-1144 | J29: 4 | K29: Active
A30: JOG-1136 | B30: Marketing | C30: Marketing Manager | D30: employees.1136@jogate.com | E30: Female | F30: 43472 | H30: 1933 | J30: 4 | K30: Active
A31: JOG-1152 | B31: Research & Development | C31: Lab Technician | D31: employees.1152@jogate.com | E31: Null | F31: 43474 | H31: 946 | I31: JOG-1192 | J31: 4 | K31: Active
A32: JOG-1058 | B32: IT Support | C32: Help Desk Specialist | D32: =_xlfn.CONCAT("employees.", RIGHT('Average salary'!$A59, 4), "@jogate.com") -> employees.1028@jogate.com | E32: Null | F32: 43504 | H32: 2088 | I32: JOG-1044 | J32: 4 | K32: Active
A33: JOG-1048 | B33: Research & Development | C33: Research Lead | D33: employees.1048@jogate.com | E33: Null | F33: 43519 | H33: 1258 | I33: JOG-1030 | J33: 5 | K33: Active
A34: JOG-1030 | B34: Marketing | C34: Marketing Manager | D34: employees.1030@jogate.com | E34: Male | F34: 43530 | H34: 953 | J34: 5 | K34: Active
A35: JOG-1054 | B35: Logistics | C35: Warehouse Associate | D35: =_xlfn.CONCAT("employees.", RIGHT('Average salary'!$A55, 4), "@jogate.com") -> employees.1066@jogate.com | E35: Null | F35: 43531 | H35: 1632 | I35: JOG-1095 | J35: 3 | K35: Active
A36: JOG-1093 | B36: Human Resources | C36: Hr Generalist | D36: employees.1093@jogate.com | E36: Male | F36: 43534 | G36: 44606 | H36: 1750 | I36: JOG-1095 | J36: 4 | K36: Terminated
A37: JOG-1134 | B37: Logistics | C37: Logistics Coordinator | D37: employees.1134@jogate.com | E37: Male | F37: 43545 | H37: 1986 | I37: JOG-1165 | J37: 5 | K37: Active
A38: JOG-1147 | B38: Quality Control | C38: Qc Inspector | D38: employees.1147@jogate.com | E38: Male | F38: 43553 | H38: 1250 | I38: JOG-1094 | J38: 2 | K38: Active
A39: JOG-1099 | B39: Production | C39: Operations Manager | D39: employees.1099@jogate.com | E39: Male | F39: 43560 | H39: 1039 | J39: 3 | K39: Active
A40: JOG-1140 | B40: Production | C40: Operations Manager | D40: employees.1140@jogate.com | E40: Null | F40: 43560 | H40: 448 | J40: 4 | K40: Active
...

Sheet Turnover by department
A1: EmployeeID | B1: Department | C1: JobTitle | D1: Email | E1: Gender | F1: HireDate | G1: TerminationDate | H1: Salary | I1: ManagerID | J1: PerformanceRating | K1: Status | L1: Column12
A2: JOG-1159 | B2: Research & Development | C2: Scientist | D2: employees.1159@jogate.com | E2: Null | F2: 43120 | H2: 403 | I2: JOG-1048 | J2: 2 | K2: Active | N2: HR Analysis Project Questions and Answers
A3: JOG-1033 | B3: IT Support | C3: Help Desk Specialist | D3: employees.1033@jogate.com | E3: Female | F3: 43130 | H3: 1785 | I3: JOG-1107 | J3: 4 | K3: Active
A4: JOG-1163 | B4: Logistics | C4: Logistics Coordinator | D4: employees.1163@jogate.com | E4: Female | F4: 43138 | G4: 44980 | H4: 551 | I4: JOG-1164 | J4: 3 | K4: Terminated
A5: JOG-1014 | B5: Finance | C5: Controller | D5: employees.1014@jogate.com | E5: Female | F5: 43162 | H5: 1150 | I5: JOG-1164 | J5: 2 | K5: Active
A6: JOG-1122 | B6: Quality Control | C6: Qc Inspector | D6: employees.1122@jogate.com | E6: Null | F6: 43171 | H6: 1528 | I6: JOG-1044 | J6: 5 | K6: Active | N6: What is the average salary? | O6: The employees average salary is: | P6: =AVERAGE(H2:H201) -> 1201.815
A7: JOG-1095 | B7: Marketing | C7: Marketing Manager | D7: employees.1095@jogate.com | E7: Female | F7: 43184 | G7: 44764 | H7: 1696 | J7: 5 | K7: Terminated
A8: JOG-1131 | B8: Human Resources | C8: Hr Coordinator | D8: employees.1131@jogate.com | E8: Female | F8: 43189 | H8: 338 | I8: JOG-1174 | J8: 3 | K8: Active
A9: JOG-1052 | B9: Research & Development | C9: Research Lead | D9: employees.1052@jogate.com | E9: Female | F9: 43200 | H9: 318 | I9: JOG-1136 | J9: 2 | K9: Active
A10: JOG-1182 | B10: Sales | C10: Regional Sales Manager | D10: employees.1182@jogate.com | E10: Female | F10: 43205 | H10: 1646 | J10: 2 | K10: Active
A11: JOG-1172 | B11: Production | C11: Operations Manager | D11: employees.1172@jogate.com | E11: Male | F11: 43229 | H11: 1440 | J11: 3 | K11: Active
A12: JOG-1192 | B12: Quality Control | C12: Qc Manager | D12: employees.1192@jogate.com | E12: Null | F12: 43229 | G12: 44618 | H12: 2082 | J12: 2 | K12: Terminated
A13: JOG-1130 | B13: Human Resources | C13: Hr Generalist | D13: employees.1130@jogate.com | E13: Null | F13: 43244 | H13: 1088 | I13: JOG-1064 | J13: 3 | K13: Active
A14: JOG-1155 | B14: Human Resources | C14: Recruiter | D14: employees.1155@jogate.com | E14: Null | F14: 43263 | H14: 1236 | I14: JOG-1198 | J14: 5 | K14: Active | N14: Status | O14: Terminated
A15: JOG-1084 | B15: Logistics | C15: Warehouse Associate | D15: employees.1084@jogate.com | E15: Male | F15: 43280 | H15: 1554 | I15: JOG-1120 | J15: 4 | K15: Active
A16: JOG-1144 | B16: Production | C16: Operations Manager | D16: employees.1144@jogate.com | E16: Male | F16: 43289 | H16: 814 | J16: 5 | K16: Active | N16: Row Labels | O16: Count of EmployeeID
A17: JOG-1107 | B17: Quality Control | C17: Qc Manager | D17: =_xlfn.CONCAT("employees.", RIGHT('Turnover by department'!$A108, 4), "@jogate.com") -> employees.1022@jogate.com | E17: Male | F17: 43292 | G17: 44267 | H17: 1594 | J17: 2 | K17: Terminated | N17: Logistics | O17: 6
A18: JOG-1123 | B18: Research & Development | C18: Scientist | D18: employees.1123@jogate.com | E18: Female | F18: 43308 | H18: 1591 | I18: JOG-1044 | J18: 5 | K18: Active | N18: Human Resources | O18: 6
A19: JOG-1156 | B19: Finance | C19: Accountant | D19: employees.1156@jogate.com | E19: Null | F19: 43323 | H19: 1899 | I19: JOG-1050 | J19: 2 | K19: Active | N19: Production | O19: 5
A20: JOG-1174 | B20: Quality Control | C20: Qc Manager | D20: employees.1174@jogate.com | E20: Null | F20: 43336 | H20: 1529 | J20: 3 | K20: Active | N20: Quality Control | O20: 5
A21: JOG-1073 | B21: Production | C21: Line Supervisor | D21: employees.1073@jogate.com | E21: Female | F21: 43337 | G21: 44278 | H21: 1593 | I21: JOG-1050 | J21: 3 | K21: Terminated | N21: Marketing | O21: 4
A22: JOG-1135 | B22: Quality Control | C22: Qc Manager | D22: employees.1135@jogate.com | E22: Male | F22: 43345 | H22: 1820 | J22: 4 | K22: Active | N22: Research & Development | O22: 3
A23: JOG-1043 | B23: Research & Development | C23: Research Lead | D23: employees.1043@jogate.com | E23: Female | F23: 43349 | G23: 45081 | H23: 1802 | I23: JOG-1107 | J23: 5 | K23: Terminated | N23: Sales | O23: 3
A24: JOG-1117 | B24: Finance | C24: Controller | D24: employees.1117@jogate.com | E24: Null | F24: 43349 | H24: 1009 | I24: JOG-1060 | J24: 2 | K24: Active | N24: Finance | O24: 3
A25: JOG-1024 | B25: IT Support | C25: Help Desk Specialist | D25: =_xlfn.CONCAT("employees.", RIGHT('Turnover by department'!$A25, 4), "@jogate.com") -> employees.1024@jogate.com | E25: Female | F25: 43353 | H25: 761 | I25: JOG-1120 | J25: 4 | K25: Active | N25: IT Support | O25: 1
A26: JOG-1145 | B26: Sales | C26: Sales Associate | D26: employees.1145@jogate.com | E26: Male | F26: 43404 | H26: 994 | I26: JOG-1006 | J26: 5 | K26: Active | N26: Grand Total | O26: 36
A27: JOG-1092 | B27: Production | C27: Production Worker | D27: employees.1092@jogate.com | E27: Null | F27: 43414 | H27: 466 | I27: JOG-1060 | J27: 5 | K27: Active
A28: JOG-1020 | B28: Finance | C28: Financial Analyst | D28: =_xlfn.CONCAT("employees.", RIGHT('Turnover by department'!$A21, 4), "@jogate.com") -> employees.1073@jogate.com | E28: Male | F28: 43455 | G28: 44930 | H28: 1814 | I28: JOG-1064 | J28: 2 | K28: Terminated
A29: JOG-1031 | B29: Finance | C29: Accountant | D29: employees.1031@jogate.com | E29: Null | F29: 43456 | H29: 454 | I29: JOG-1144 | J29: 4 | K29: Active
A30: JOG-1136 | B30: Marketing | C30: Marketing Manager | D30: employees.1136@jogate.com | E30: Female | F30: 43472 | H30: 1933 | J30: 4 | K30: Active
A31: JOG-1152 | B31: Research & Development | C31: Lab Technician | D31: employees.1152@jogate.com | E31: Null | F31: 43474 | H31: 946 | I31: JOG-1192 | J31: 4 | K31: Active
A32: JOG-1058 | B32: IT Support | C32: Help Desk Specialist | D32: =_xlfn.CONCAT("employees.", RIGHT('Turnover by department'!$A59, 4), "@jogate.com") -> employees.1028@jogate.com | E32: Null | F32: 43504 | H32: 2088 | I32: JOG-1044 | J32: 4 | K32: Active
A33: JOG-1048 | B33: Research & Development | C33: Research Lead | D33: employees.1048@jogate.com | E33: Null | F33: 43519 | H33: 1258 | I33: JOG-1030 | J33: 5 | K33: Active
A34: JOG-1030 | B34: Marketing | C34: Marketing Manager | D34: employees.1030@jogate.com | E34: Male | F34: 43530 | H34: 953 | J34: 5 | K34: Active
A35: JOG-1054 | B35: Logistics | C35: Warehouse Associate | D35: =_xlfn.CONCAT("employees.", RIGHT('Turnover by department'!$A55, 4), "@jogate.com") -> employees.1066@jogate.com | E35: Null | F35: 43531 | H35: 1632 | I35: JOG-1095 | J35: 3 | K35: Active
A36: JOG-1093 | B36: Human Resources | C36: Hr Generalist | D36: employees.1093@jogate.com | E36: Male | F36: 43534 | G36: 44606 | H36: 1750 | I36: JOG-1095 | J36: 4 | K36: Terminated
A37: JOG-1134 | B37: Logistics | C37: Logistics Coordinator | D37: employees.1134@jogate.com | E37: Male | F37: 43545 | H37: 1986 | I37: JOG-1165 | J37: 5 | K37: Active
A38: JOG-1147 | B38: Quality Control | C38: Qc Inspector | D38: employees.1147@jogate.com | E38: Male | F38: 43553 | H38: 1250 | I38: JOG-1094 | J38: 2 | K38: Active
A39: JOG-1099 | B39: Production | C39: Operations Manager | D39: employees.1099@jogate.com | E39: Male | F39: 43560 | H39: 1039 | J39: 3 | K39: Active
A40: JOG-1140 | B40: Production | C40: Operations Manager | D40: employees.1140@jogate.com | E40: Null | F40: 43560 | H40: 448 | J40: 4 | K40: Active
...

Sheet Terminated by gender
A1: EmployeeID | B1: Department | C1: JobTitle | D1: Email | E1: Gender | F1: HireDate | G1: TerminationDate | H1: Salary | I1: ManagerID | J1: PerformanceRating | K1: Status | L1: Column12
A2: JOG-1159 | B2: Research & Development | C2: Scientist | D2: employees.1159@jogate.com | E2: Null | F2: 43120 | H2: 403 | I2: JOG-1048 | J2: 2 | K2: Active | N2: HR Analysis Project Questions and Answers
A3: JOG-1033 | B3: IT Support | C3: Help Desk Specialist | D3: employees.1033@jogate.com | E3: Female | F3: 43130 | H3: 1785 | I3: JOG-1107 | J3: 4 | K3: Active
A4: JOG-1163 | B4: Logistics | C4: Logistics Coordinator | D4: employees.1163@jogate.com | E4: Female | F4: 43138 | G4: 44980 | H4: 551 | I4: JOG-1164 | J4: 3 | K4: Terminated
A5: JOG-1014 | B5: Finance | C5: Controller | D5: employees.1014@jogate.com | E5: Female | F5: 43162 | H5: 1150 | I5: JOG-1164 | J5: 2 | K5: Active
A6: JOG-1122 | B6: Quality Control | C6: Qc Inspector | D6: employees.1122@jogate.com | E6: Null | F6: 43171 | H6: 1528 | I6: JOG-1044 | J6: 5 | K6: Active | N6: What is the average salary? | O6: The employees average salary is: | P6: =AVERAGE(H2:H201) -> 1201.815
A7: JOG-1095 | B7: Marketing | C7: Marketing Manager | D7: employees.1095@jogate.com | E7: Female | F7: 43184 | G7: 44764 | H7: 1696 | J7: 5 | K7: Terminated
A8: JOG-1131 | B8: Human Resources | C8: Hr Coordinator | D8: employees.1131@jogate.com | E8: Female | F8: 43189 | H8: 338 | I8: JOG-1174 | J8: 3 | K8: Active
A9: JOG-1052 | B9: Research & Development | C9: Research Lead | D9: employees.1052@jogate.com | E9: Female | F9: 43200 | H9: 318 | I9: JOG-1136 | J9: 2 | K9: Active
A10: JOG-1182 | B10: Sales | C10: Regional Sales Manager | D10: employees.1182@jogate.com | E10: Female | F10: 43205 | H10: 1646 | J10: 2 | K10: Active
A11: JOG-1172 | B11: Production | C11: Operations Manager | D11: employees.1172@jogate.com | E11: Male | F11: 43229 | H11: 1440 | J11: 3 | K11: Active
A12: JOG-1192 | B12: Quality Control | C12: Qc Manager | D12: employees.1192@jogate.com | E12: Null | F12: 43229 | G12: 44618 | H12: 2082 | J12: 2 | K12: Terminated
A13: JOG-1130 | B13: Human Resources | C13: Hr Generalist | D13: employees.1130@jogate.com | E13: Null | F13: 43244 | H13: 1088 | I13: JOG-1064 | J13: 3 | K13: Active
A14: JOG-1155 | B14: Human Resources | C14: Recruiter | D14: employees.1155@jogate.com | E14: Null | F14: 43263 | H14: 1236 | I14: JOG-1198 | J14: 5 | K14: Active | N14: Status | O14: Terminated
A15: JOG-1084 | B15: Logistics | C15: Warehouse Associate | D15: employees.1084@jogate.com | E15: Male | F15: 43280 | H15: 1554 | I15: JOG-1120 | J15: 4 | K15: Active
A16: JOG-1144 | B16: Production | C16: Operations Manager | D16: employees.1144@jogate.com | E16: Male | F16: 43289 | H16: 814 | J16: 5 | K16: Active | N16: Count of EmployeeID | O16: Column Labels
A17: JOG-1107 | B17: Quality Control | C17: Qc Manager | D17: =_xlfn.CONCAT("employees.", RIGHT('Terminated by gender'!$A108, 4), "@jogate.com") -> employees.1022@jogate.com | E17: Male | F17: 43292 | G17: 44267 | H17: 1594 | J17: 2 | K17: Terminated | N17: Row Labels | O17: Female | P17: Male | Q17: Grand Total
A18: JOG-1123 | B18: Research & Development | C18: Scientist | D18: employees.1123@jogate.com | E18: Female | F18: 43308 | H18: 1591 | I18: JOG-1044 | J18: 5 | K18: Active | N18: Finance | P18: 1 | Q18: 1
A19: JOG-1156 | B19: Finance | C19: Accountant | D19: employees.1156@jogate.com | E19: Null | F19: 43323 | H19: 1899 | I19: JOG-1050 | J19: 2 | K19: Active | N19: Human Resources | O19: 2 | P19: 1 | Q19: 3
A20: JOG-1174 | B20: Quality Control | C20: Qc Manager | D20: employees.1174@jogate.com | E20: Null | F20: 43336 | H20: 1529 | J20: 3 | K20: Active | N20: IT Support | O20: 1 | Q20: 1
A21: JOG-1073 | B21: Production | C21: Line Supervisor | D21: employees.1073@jogate.com | E21: Female | F21: 43337 | G21: 44278 | H21: 1593 | I21: JOG-1050 | J21: 3 | K21: Terminated | N21: Logistics | O21: 2 | P21: 1 | Q21: 3
A22: JOG-1135 | B22: Quality Control | C22: Qc Manager | D22: employees.1135@jogate.com | E22: Male | F22: 43345 | H22: 1820 | J22: 4 | K22: Active | N22: Marketing | O22: 1 | P22: 1 | Q22: 2
A23: JOG-1043 | B23: Research & Development | C23: Research Lead | D23: employees.1043@jogate.com | E23: Female | F23: 43349 | G23: 45081 | H23: 1802 | I23: JOG-1107 | J23: 5 | K23: Terminated | N23: Production | O23: 5 | Q23: 5
A24: JOG-1117 | B24: Finance | C24: Controller | D24: employees.1117@jogate.com | E24: Null | F24: 43349 | H24: 1009 | I24: JOG-1060 | J24: 2 | K24: Active | N24: Quality Control | O24: 2 | P24: 1 | Q24: 3
A25: JOG-1024 | B25: IT Support | C25: Help Desk Specialist | D25: =_xlfn.CONCAT("employees.", RIGHT('Terminated by gender'!$A25, 4), "@jogate.com") -> employees.1024@jogate.com | E25: Female | F25: 43353 | H25: 761 | I25: JOG-1120 | J25: 4 | K25: Active | N25: Research & Development | O25: 2 | Q25: 2
A26: JOG-1145 | B26: Sales | C26: Sales Associate | D26: employees.1145@jogate.com | E26: Male | F26: 43404 | H26: 994 | I26: JOG-1006 | J26: 5 | K26: Active | N26: Sales | O26: 2 | Q26: 2
A27: JOG-1092 | B27: Production | C27: Production Worker | D27: employees.1092@jogate.com | E27: Null | F27: 43414 | H27: 466 | I27: JOG-1060 | J27: 5 | K27: Active | N27: Grand Total | O27: 17 | P27: 5 | Q27: 22
A28: JOG-1020 | B28: Finance | C28: Financial Analyst | D28: =_xlfn.CONCAT("employees.", RIGHT('Terminated by gender'!$A21, 4), "@jogate.com") -> employees.1073@jogate.com | E28: Male | F28: 43455 | G28: 44930 | H28: 1814 | I28: JOG-1064 | J28: 2 | K28: Terminated
A29: JOG-1031 | B29: Finance | C29: Accountant | D29: employees.1031@jogate.com | E29: Null | F29: 43456 | H29: 454 | I29: JOG-1144 | J29: 4 | K29: Active
A30: JOG-1136 | B30: Marketing | C30: Marketing Manager | D30: employees.1136@jogate.com | E30: Female | F30: 43472 | H30: 1933 | J30: 4 | K30: Active
A31: JOG-1152 | B31: Research & Development | C31: Lab Technician | D31: employees.1152@jogate.com | E31: Null | F31: 43474 | H31: 946 | I31: JOG-1192 | J31: 4 | K31: Active
A32: JOG-1058 | B32: IT Support | C32: Help Desk Specialist | D32: =_xlfn.CONCAT("employees.", RIGHT('Terminated by gender'!$A59, 4), "@jogate.com") -> employees.1028@jogate.com | E32: Null | F32: 43504 | H32: 2088 | I32: JOG-1044 | J32: 4 | K32: Active
A33: JOG-1048 | B33: Research & Development | C33: Research Lead | D33: employees.1048@jogate.com | E33: Null | F33: 43519 | H33: 1258 | I33: JOG-1030 | J33: 5 | K33: Active
A34: JOG-1030 | B34: Marketing | C34: Marketing Manager | D34: employees.1030@jogate.com | E34: Male | F34: 43530 | H34: 953 | J34: 5 | K34: Active
A35: JOG-1054 | B35: Logistics | C35: Warehouse Associate | D35: =_xlfn.CONCAT("employees.", RIGHT('Terminated by gender'!$A55, 4), "@jogate.com") -> employees.1066@jogate.com | E35: Null | F35: 43531 | H35: 1632 | I35: JOG-1095 | J35: 3 | K35: Active
A36: JOG-1093 | B36: Human Resources | C36: Hr Generalist | D36: employees.1093@jogate.com | E36: Male | F36: 43534 | G36: 44606 | H36: 1750 | I36: JOG-1095 | J36: 4 | K36: Terminated
A37: JOG-1134 | B37: Logistics | C37: Logistics Coordinator | D37: employees.1134@jogate.com | E37: Male | F37: 43545 | H37: 1986 | I37: JOG-1165 | J37: 5 | K37: Active
A38: JOG-1147 | B38: Quality Control | C38: Qc Inspector | D38: employees.1147@jogate.com | E38: Male | F38: 43553 | H38: 1250 | I38: JOG-1094 | J38: 2 | K38: Active
A39: JOG-1099 | B39: Production | C39: Operations Manager | D39: employees.1099@jogate.com | E39: Male | F39: 43560 | H39: 1039 | J39: 3 | K39: Active
A40: JOG-1140 | B40: Production | C40: Operations Manager | D40: employees.1140@jogate.com | E40: Null | F40: 43560 | H40: 448 | J40: 4 | K40: Active
...
